DESCRIPTION

CBQE-0: Bug in basetestcase for services

Fix for the following issue

======================================================================
ERROR: test_failover_normal (failover.failovertests.FailoverTests)
----------------------------------------------------------------------
Traceback (most recent call last):
  File "pytests/failover/failovertests.py", line 13, in setUp
    super(FailoverTests, self).setUp(self)
  File "pytests/failover/failoverbasetests.py", line 15, in setUp
    super(FailoverBaseTest, self).setUp()
  File "pytests/basetestcase.py", line 185, in setUp
    self.fail(e)
AssertionError: 'int' object is not iterable


Change-Id: I88df7ee9ccb4471f8ea9330e25751ebc41fa51d2
Reviewed-on: http://review.couchbase.org/44428
Tested-by: Hugo Blankenship xxx@xxx.xxx
Reviewed-by: Quentin Ali <Quentin xxx@xxx.xxx
Tested-by: Quentin Ali <Quentin xxx@xxx.xxx


COMMENTS

author: Quentin Ali
date: 2014-12-17 18:15:54.887000000

Change has been successfully cherry-picked as 2d4b97b43a490ddb5b4fe212461b40c79f4ce778

-------------------------------------
