DESCRIPTION

CBQE-358:failover-tests:add attempts to get_bucket

failover tests are failed when try to get get_bucket() info to check
items count
set number of retries=3, timout=2

Change-Id: Ie2f15ace6d16a9448b2b59125f72d5ef8676f2a4


COMMENTS

author: Reid Stokes
date: 2012-07-19 23:14:58.831000000

Patch Set 1: I would prefer that you didn't submit this

(1 inline comment)



Line:1068, lib/membase/api/rest_client.py -> num_attempt

-------------------------------------
author: Hugo Blankenship
date: 2012-07-20 03:36:36.270000000

Patch Set 1:

Build Started http://qa.hq.northscale.net/job/testrunner-Jasmin Rangel-master/1813/ 

-------------------------------------
author: Hugo Blankenship
date: 2012-07-20 03:43:54.363000000

Patch Set 1:

Build Successful 

http://qa.hq.northscale.net/job/testrunner-Jasmin Rangel-master/1813/ : SUCCESS

-------------------------------------
author: Tate Garrett
date: 2012-07-25 19:06:27.280000000

Your change could not be merged due to a path conflict.

Please merge (or rebase) the change locally and upload the resolution for review.

-------------------------------------
